Workbook

Sheet List Data
A1: Sumber Pendanaan | B1: Barang | C1: Kategori Barang | D1: Jumlah Masuk | E1: Jumlah Keluar | F1: Kab/Kota Tujuan | G1: Tanggal Kadaluwarsa | H1: Tanggal barang diterima | I1: Tanggal barang dikeluarkan | J1: Nomor Dokumen | K1: Harga Satuan (Rp) | L1: Nilai Total (Rp)
A2: APBN | B2: Matras | C2: Sandang | D2: 600 | E2: 0 | F2: - | H2: 45658 | J2: BAST-2025-IN-0001 | K2: 120000 | L2: 72000000
A3: APBN | B3: Matras | C3: Sandang | D3: 800 | E3: 0 | F3: - | H3: 45661 | J3: BAST-2025-IN-0002 | K3: 120000 | L3: 96000000
A4: APBN | B4: Genset | C4: Logistik Lainnya | D4: 20 | E4: 0 | F4: - | H4: 45664 | J4: BAST-2025-IN-0003 | K4: 12500000 | L4: 250000000
A5: APBD | B5: Perahu Karet | C5: Logistik Lainnya | D5: 8 | E5: 0 | F5: - | H5: 45665 | J5: BAST-2025-IN-0004 | K5: 35000000 | L5: 280000000
A6: CSR | B6: Pakaian Anak | C6: Sandang | D6: 1600 | E6: 0 | F6: - | H6: 45669 | J6: BAST-2025-IN-0005 | K6: 75000 | L6: 120000000
A7: CSR | B7: Family Kit | C7: Logistik Lainnya | D7: 1050 | E7: 0 | F7: - | H7: 45677 | J7: BAST-2025-IN-0006 | K7: 350000 | L7: 367500000
A8: APBN | B8: Perahu Karet | C8: Logistik Lainnya | D8: 15 | E8: 0 | F8: - | H8: 45679 | J8: BAST-2025-IN-0007 | K8: 35000000 | L8: 525000000
A9: APBN | B9: Pakaian Dewasa | C9: Sandang | D9: 550 | E9: 0 | F9: - | H9: 45683 | J9: BAST-2025-IN-0008 | K9: 95000 | L9: 52250000
A10: APBD | B10: Tenda Pengungsi | C10: Papan | D10: 110 | E10: 0 | F10: - | H10: 45685 | J10: BAST-2025-IN-0009 | K10: 8500000 | L10: 935000000
A11: APBD | B11: Seng | C11: Papan | D11: 1950 | E11: 0 | F11: - | H11: 45688 | J11: BAST-2025-IN-0010 | K11: 90000 | L11: 175500000
A12: APBN | B12: Pakaian Dewasa | C12: Sandang | D12: 400 | E12: 0 | F12: - | H12: 45690 | J12: BAST-2025-IN-0011 | K12: 95000 | L12: 38000000
A13: APBD | B13: Air Mineral | C13: Pangan | D13: 1350 | E13: 0 | F13: - | G13: 46558 | H13: 45690 | J13: BAST-2025-IN-0012 | K13: 30000 | L13: 40500000
A14: APBN | B14: Terpal | C14: Papan | D14: 450 | E14: 0 | F14: - | H14: 45702 | J14: BAST-2025-IN-0013 | K14: 150000 | L14: 67500000
A15: APBD | B15: Seng | C15: Papan | D15: 700 | E15: 0 | F15: - | H15: 45704 | J15: BAST-2025-IN-0014 | K15: 90000 | L15: 63000000
A16: APBN | B16: Seng | C16: Papan | D16: 1850 | E16: 0 | F16: - | H16: 45706 | J16: BAST-2025-IN-0015 | K16: 90000 | L16: 166500000
A17: CSR | B17: Pakaian Dewasa | C17: Sandang | D17: 400 | E17: 0 | F17: - | H17: 45715 | J17: BAST-2025-IN-0016 | K17: 95000 | L17: 38000000
A18: CSR | B18: Selimut | C18: Sandang | D18: 350 | E18: 0 | F18: - | H18: 45717 | J18: BAST-2025-IN-0017 | K18: 85000 | L18: 29750000
A19: APBN | B19: Beras | C19: Pangan | D19: 7650 | E19: 0 | F19: - | G19: 46384 | H19: 45723 | J19: BAST-2025-IN-0018 | K19: 15000 | L19: 114750000
A20: APBN | B20: Beras | C20: Pangan | D20: 7200 | E20: 0 | F20: - | G20: 46411 | H20: 45723 | J20: BAST-2025-IN-0019 | K20: 15000 | L20: 108000000
A21: APBD | B21: Terpal | C21: Papan | D21: 1050 | E21: 0 | F21: - | H21: 45725 | J21: BAST-2025-IN-0020 | K21: 150000 | L21: 157500000
A22: APBN | B22: Makanan Siap Saji | C22: Pangan | D22: 2900 | E22: 0 | F22: - | G22: 46267 | H22: 45728 | J22: BAST-2025-IN-0021 | K22: 45000 | L22: 130500000
A23: APBD | B23: Matras | C23: Sandang | D23: 250 | E23: 0 | F23: - | H23: 45729 | J23: BAST-2025-IN-0022 | K23: 120000 | L23: 30000000
A24: CSR | B24: Perahu Karet | C24: Logistik Lainnya | D24: 18 | E24: 0 | F24: - | H24: 45731 | J24: BAST-2025-IN-0023 | K24: 35000000 | L24: 630000000
A25: APBN | B25: Lauk Pauk | C25: Pangan | D25: 0 | E25: 300 | F25: Kabupaten Bandung Barat | I25: 45733 | J25: SJ-2025-OUT-0001 | K25: 35000 | L25: 10500000
A26: CSR | B26: Beras | C26: Pangan | D26: 1900 | E26: 0 | F26: - | H26: 45738 | J26: BAST-2025-IN-0024 | K26: 15000 | L26: 28500000
A27: APBN | B27: Beras | C27: Pangan | D27: 2100 | E27: 0 | F27: - | G27: 46314 | H27: 45738 | J27: BAST-2025-IN-0025 | K27: 15000 | L27: 31500000
A28: APBD | B28: Pakaian Dewasa | C28: Sandang | D28: 1200 | E28: 0 | F28: - | H28: 45739 | J28: BAST-2025-IN-0026 | K28: 95000 | L28: 114000000
A29: CSR | B29: Sanitasi Kit | C29: Logistik Lainnya | D29: 150 | E29: 0 | F29: - | G29: 46468 | H29: 45745 | J29: BAST-2025-IN-0027 | K29: 250000 | L29: 37500000
A30: APBD | B30: Biskuit | C30: Pangan | D30: 1100 | E30: 0 | F30: - | H30: 45747 | J30: BAST-2025-IN-0028 | K30: 25000 | L30: 27500000
A31: APBD | B31: Susu Formula | C31: Pangan | D31: 600 | E31: 0 | F31: - | G31: 46177 | H31: 45751 | J31: BAST-2025-IN-0029 | K31: 65000 | L31: 39000000
A32: APBD | B32: Air Mineral | C32: Pangan | D32: 1050 | E32: 0 | F32: - | G32: 46442 | H32: 45752 | J32: BAST-2025-IN-0030 | K32: 30000 | L32: 31500000
A33: APBN | B33: Chainsaw | C33: Logistik Lainnya | D33: 18 | E33: 0 | F33: - | H33: 45753 | J33: BAST-2025-IN-0031 | K33: 4500000 | L33: 81000000
A34: APBD | B34: Matras | C34: Sandang | D34: 0 | E34: 375 | F34: Kabupaten Majalengka | I34: 45754 | J34: SJ-2025-OUT-0002 | K34: 120000 | L34: 45000000
A35: APBD | B35: Terpal | C35: Papan | D35: 0 | E35: 175 | F35: Kabupaten Garut | I35: 45755 | J35: SJ-2025-OUT-0003 | K35: 150000 | L35: 26250000
A36: CSR | B36: Biskuit | C36: Pangan | D36: 800 | E36: 0 | F36: - | H36: 45757 | J36: BAST-2025-IN-0032 | K36: 25000 | L36: 20000000
A37: APBN | B37: Susu Formula | C37: Pangan | D37: 850 | E37: 0 | F37: - | G37: 46188 | H37: 45761 | J37: BAST-2025-IN-0033 | K37: 65000 | L37: 55250000
A38: CSR | B38: Genset | C38: Logistik Lainnya | D38: 5 | E38: 0 | F38: - | H38: 45762 | J38: BAST-2025-IN-0034 | K38: 12500000 | L38: 62500000
A39: CSR | B39: Lauk Pauk | C39: Pangan | D39: 1200 | E39: 0 | F39: - | H39: 45762 | J39: BAST-2025-IN-0035 | K39: 35000 | L39: 42000000
A40: CSR | B40: Terpal | C40: Papan | D40: 0 | E40: 625 | F40: Kota Bogor | I40: 45762 | J40: SJ-2025-OUT-0004 | K40: 150000 | L40: 93750000
...

Sheet Penerimaan
A1: Sumber Pendanaan | B1: Barang | C1: Kategori Barang | D1: Jumlah Masuk | E1: Tanggal Kadaluwarsa | F1: Tanggal barang diterima | G1: Nomor Dokumen | H1: Harga Satuan (Rp) | I1: Nilai Total (Rp)
A2: APBN | B2: Matras | C2: Sandang | D2: 600 | F2: 45658 | G2: BAST-2025-IN-0001 | H2: 120000 | I2: 72000000
A3: APBN | B3: Matras | C3: Sandang | D3: 800 | F3: 45661 | G3: BAST-2025-IN-0002 | H3: 120000 | I3: 96000000
A4: APBN | B4: Genset | C4: Logistik Lainnya | D4: 20 | F4: 45664 | G4: BAST-2025-IN-0003 | H4: 12500000 | I4: 250000000
A5: APBD | B5: Perahu Karet | C5: Logistik Lainnya | D5: 8 | F5: 45665 | G5: BAST-2025-IN-0004 | H5: 35000000 | I5: 280000000
A6: CSR | B6: Pakaian Anak | C6: Sandang | D6: 1600 | F6: 45669 | G6: BAST-2025-IN-0005 | H6: 75000 | I6: 120000000
A7: CSR | B7: Family Kit | C7: Logistik Lainnya | D7: 1050 | F7: 45677 | G7: BAST-2025-IN-0006 | H7: 350000 | I7: 367500000
A8: APBN | B8: Perahu Karet | C8: Logistik Lainnya | D8: 15 | F8: 45679 | G8: BAST-2025-IN-0007 | H8: 35000000 | I8: 525000000
A9: APBN | B9: Pakaian Dewasa | C9: Sandang | D9: 550 | F9: 45683 | G9: BAST-2025-IN-0008 | H9: 95000 | I9: 52250000
A10: APBD | B10: Tenda Pengungsi | C10: Papan | D10: 110 | F10: 45685 | G10: BAST-2025-IN-0009 | H10: 8500000 | I10: 935000000
A11: APBD | B11: Seng | C11: Papan | D11: 1950 | F11: 45688 | G11: BAST-2025-IN-0010 | H11: 90000 | I11: 175500000
A12: APBN | B12: Pakaian Dewasa | C12: Sandang | D12: 400 | F12: 45690 | G12: BAST-2025-IN-0011 | H12: 95000 | I12: 38000000
A13: APBD | B13: Air Mineral | C13: Pangan | D13: 1350 | E13: 46558 | F13: 45690 | G13: BAST-2025-IN-0012 | H13: 30000 | I13: 40500000
A14: APBN | B14: Terpal | C14: Papan | D14: 450 | F14: 45702 | G14: BAST-2025-IN-0013 | H14: 150000 | I14: 67500000
A15: APBD | B15: Seng | C15: Papan | D15: 700 | F15: 45704 | G15: BAST-2025-IN-0014 | H15: 90000 | I15: 63000000
A16: APBN | B16: Seng | C16: Papan | D16: 1850 | F16: 45706 | G16: BAST-2025-IN-0015 | H16: 90000 | I16: 166500000
A17: CSR | B17: Pakaian Dewasa | C17: Sandang | D17: 400 | F17: 45715 | G17: BAST-2025-IN-0016 | H17: 95000 | I17: 38000000
A18: CSR | B18: Selimut | C18: Sandang | D18: 350 | F18: 45717 | G18: BAST-2025-IN-0017 | H18: 85000 | I18: 29750000
A19: APBN | B19: Beras | C19: Pangan | D19: 7650 | E19: 46384 | F19: 45723 | G19: BAST-2025-IN-0018 | H19: 15000 | I19: 114750000
A20: APBN | B20: Beras | C20: Pangan | D20: 7200 | E20: 46411 | F20: 45723 | G20: BAST-2025-IN-0019 | H20: 15000 | I20: 108000000
A21: APBD | B21: Terpal | C21: Papan | D21: 1050 | F21: 45725 | G21: BAST-2025-IN-0020 | H21: 150000 | I21: 157500000
A22: APBN | B22: Makanan Siap Saji | C22: Pangan | D22: 2900 | E22: 46267 | F22: 45728 | G22: BAST-2025-IN-0021 | H22: 45000 | I22: 130500000
A23: APBD | B23: Matras | C23: Sandang | D23: 250 | F23: 45729 | G23: BAST-2025-IN-0022 | H23: 120000 | I23: 30000000
A24: CSR | B24: Perahu Karet | C24: Logistik Lainnya | D24: 18 | F24: 45731 | G24: BAST-2025-IN-0023 | H24: 35000000 | I24: 630000000
A25: CSR | B25: Beras | C25: Pangan | D25: 1900 | F25: 45738 | G25: BAST-2025-IN-0024 | H25: 15000 | I25: 28500000
A26: APBN | B26: Beras | C26: Pangan | D26: 2100 | E26: 46314 | F26: 45738 | G26: BAST-2025-IN-0025 | H26: 15000 | I26: 31500000
A27: APBD | B27: Pakaian Dewasa | C27: Sandang | D27: 1200 | F27: 45739 | G27: BAST-2025-IN-0026 | H27: 95000 | I27: 114000000
A28: CSR | B28: Sanitasi Kit | C28: Logistik Lainnya | D28: 150 | E28: 46468 | F28: 45745 | G28: BAST-2025-IN-0027 | H28: 250000 | I28: 37500000
A29: APBD | B29: Biskuit | C29: Pangan | D29: 1100 | F29: 45747 | G29: BAST-2025-IN-0028 | H29: 25000 | I29: 27500000
A30: APBD | B30: Susu Formula | C30: Pangan | D30: 600 | E30: 46177 | F30: 45751 | G30: BAST-2025-IN-0029 | H30: 65000 | I30: 39000000
A31: APBD | B31: Air Mineral | C31: Pangan | D31: 1050 | E31: 46442 | F31: 45752 | G31: BAST-2025-IN-0030 | H31: 30000 | I31: 31500000
A32: APBN | B32: Chainsaw | C32: Logistik Lainnya | D32: 18 | F32: 45753 | G32: BAST-2025-IN-0031 | H32: 4500000 | I32: 81000000
A33: CSR | B33: Biskuit | C33: Pangan | D33: 800 | F33: 45757 | G33: BAST-2025-IN-0032 | H33: 25000 | I33: 20000000
A34: APBN | B34: Susu Formula | C34: Pangan | D34: 850 | E34: 46188 | F34: 45761 | G34: BAST-2025-IN-0033 | H34: 65000 | I34: 55250000
A35: CSR | B35: Genset | C35: Logistik Lainnya | D35: 5 | F35: 45762 | G35: BAST-2025-IN-0034 | H35: 12500000 | I35: 62500000
A36: CSR | B36: Lauk Pauk | C36: Pangan | D36: 1200 | F36: 45762 | G36: BAST-2025-IN-0035 | H36: 35000 | I36: 42000000
A37: APBN | B37: Biskuit | C37: Pangan | D37: 750 | F37: 45766 | G37: BAST-2025-IN-0036 | H37: 25000 | I37: 18750000
A38: CSR | B38: Pakaian Anak | C38: Sandang | D38: 700 | F38: 45770 | G38: BAST-2025-IN-0037 | H38: 75000 | I38: 52500000
A39: APBD | B39: Sanitasi Kit | C39: Logistik Lainnya | D39: 500 | F39: 45772 | G39: BAST-2025-IN-0038 | H39: 250000 | I39: 125000000
A40: APBN | B40: Biskuit | C40: Pangan | D40: 2350 | E40: 46162 | F40: 45772 | G40: BAST-2025-IN-0039 | H40: 25000 | I40: 58750000
...

Sheet Distribusi
A1: Sumber Pendanaan | B1: Barang | C1: Kategori Barang | D1: Jumlah Keluar | E1: Kab/Kota Tujuan | F1: Tanggal barang dikeluarkan | G1: Nomor Dokumen | H1: Harga Satuan (Rp) | I1: Nilai Total (Rp)
A2: APBN | B2: Lauk Pauk | C2: Pangan | D2: 300 | E2: Kabupaten Bandung Barat | F2: 45733 | G2: SJ-2025-OUT-0001 | H2: 35000 | I2: 10500000
A3: APBD | B3: Matras | C3: Sandang | D3: 375 | E3: Kabupaten Majalengka | F3: 45754 | G3: SJ-2025-OUT-0002 | H3: 120000 | I3: 45000000
A4: APBD | B4: Terpal | C4: Papan | D4: 175 | E4: Kabupaten Garut | F4: 45755 | G4: SJ-2025-OUT-0003 | H4: 150000 | I4: 26250000
A5: CSR | B5: Terpal | C5: Papan | D5: 625 | E5: Kota Bogor | F5: 45762 | G5: SJ-2025-OUT-0004 | H5: 150000 | I5: 93750000
A6: APBN | B6: Beras | C6: Pangan | D6: 3350 | E6: Kabupaten Bekasi | F6: 45788 | G6: SJ-2025-OUT-0005 | H6: 15000 | I6: 50250000
A7: CSR | B7: Tenda Keluarga | C7: Papan | D7: 70 | E7: Kabupaten Sukabumi | F7: 45794 | G7: SJ-2025-OUT-0006 | H7: 3200000 | I7: 224000000
A8: CSR | B8: Pakaian Anak | C8: Sandang | D8: 300 | E8: Kabupaten Subang | F8: 45800 | G8: SJ-2025-OUT-0007 | H8: 75000 | I8: 22500000
A9: CSR | B9: Biskuit | C9: Pangan | D9: 1075 | E9: Kabupaten Indramayu | F9: 45810 | G9: SJ-2025-OUT-0008 | H9: 25000 | I9: 26875000
A10: CSR | B10: Selimut | C10: Sandang | D10: 1050 | E10: Kabupaten Karawang | F10: 45818 | G10: SJ-2025-OUT-0009 | H10: 85000 | I10: 89250000
A11: CSR | B11: Chainsaw | C11: Logistik Lainnya | D11: 7 | E11: Kabupaten Bekasi | F11: 45820 | G11: SJ-2025-OUT-0010 | H11: 4500000 | I11: 31500000
A12: APBD | B12: Tenda Pengungsi | C12: Papan | D12: 80 | E12: Kabupaten Karawang | F12: 45820 | G12: SJ-2025-OUT-0011 | H12: 8500000 | I12: 680000000
A13: CSR | B13: Terpal | C13: Papan | D13: 300 | E13: Kabupaten Subang | F13: 45820 | G13: SJ-2025-OUT-0012 | H13: 150000 | I13: 45000000
... A51: APBD | B51: Chainsaw | C51: Logistik Lainnya | D51: 30 | E51: Kota Bekasi | F51: 46272 | G51: SJ-2026-OUT-0027 | H51: 4500000 | I51: 135000000
A52: TOTAL DISTRIBUSI | D52: =SUM(D2:D51) | I52: =SUM(I2:I51)

Sheet Stok Awal
A1: Kunci | B1: Sumber Pendanaan | C1: Barang | D1: Kategori Barang | E1: Stok Akhir Periode Sebelumnya | F1: Harga Satuan (Rp) | G1: Nilai Total (Rp)
A2: =B2&"|"&C2&"|"&D2 | B2: APBD | C2: Chainsaw | D2: Logistik Lainnya | E2: 10 | F2: 4500000 | G2: 45000000
A3: =B3&"|"&C3&"|"&D3 | B3: APBN | C3: Chainsaw | D3: Logistik Lainnya | E3: 10 | F3: 4500000 | G3: 45000000
A4: =B4&"|"&C4&"|"&D4 | B4: CSR | C4: Chainsaw | D4: Logistik Lainnya | E4: 10 | F4: 4500000 | G4: 45000000
A5: =B5&"|"&C5&"|"&D5 | B5: APBD | C5: Family Kit | D5: Logistik Lainnya | E5: 300 | F5: 350000 | G5: 105000000
A6: =B6&"|"&C6&"|"&D6 | B6: APBN | C6: Family Kit | D6: Logistik Lainnya | E6: 300 | F6: 350000 | G6: 105000000
A7: =B7&"|"&C7&"|"&D7 | B7: CSR | C7: Family Kit | D7: Logistik Lainnya | E7: 300 | F7: 350000 | G7: 105000000
A8: =B8&"|"&C8&"|"&D8 | B8: APBD | C8: Genset | D8: Logistik Lainnya | E8: 8 | F8: 12500000 | G8: 100000000
A9: =B9&"|"&C9&"|"&D9 | B9: APBN | C9: Genset | D9: Logistik Lainnya | E9: 8 | F9: 12500000 | G9: 100000000
A10: =B10&"|"&C10&"|"&D10 | B10: CSR | C10: Genset | D10: Logistik Lainnya | E10: 8 | F10: 12500000 | G10: 100000000
A11: =B11&"|"&C11&"|"&D11 | B11: APBD | C11: Perahu Karet | D11: Logistik Lainnya | E11: 5 | F11: 35000000 | G11: 175000000
A12: =B12&"|"&C12&"|"&D12 | B12: APBN | C12: Perahu Karet | D12: Logistik Lainnya | E12: 5 | F12: 35000000 | G12: 175000000
A13: =B13&"|"&C13&"|"&D13 | B13: CSR | C13: Perahu Karet | D13: Logistik Lainnya | E13: 5 | F13: 35000000 | G13: 175000000
... A61: =B61&"|"&C61&"|"&D61 | B61: CSR | C61: Selimut | D61: Sandang | E61: 400 | F61: 85000 | G61: 34000000
B62: TOTAL STOK AWAL | E62: =SUM(E2:E61) | G62: =SUM(G2:G61)

Sheet Stok
A1: Sumber Pendanaan | B1: Barang | C1: Kategori Barang | D1: Stok Fisik | E1: Harga Satuan (Rp) | F1: Nilai Total Stok (Rp)
A2: APBD | B2: Chainsaw | C2: Logistik Lainnya | D2: ='Stok Awal'!E2 + SUMIFS(Penerimaan!D:D, Penerimaan!A:A, A2, Penerimaan!B:B, B2, Penerimaan!C:C, C2) - SUMIFS(Distribusi!D:D, Distribusi!A:A, A2, Distribusi!B:B, B2, Distribusi!C:C, C2) | E2: 4500000 | F2: =D2*E2
A3: APBN | B3: Chainsaw | C3: Logistik Lainnya | D3: ='Stok Awal'!E3 + SUMIFS(Penerimaan!D:D, Penerimaan!A:A, A3, Penerimaan!B:B, B3, Penerimaan!C:C, C3) - SUMIFS(Distribusi!D:D, Distribusi!A:A, A3, Distribusi!B:B, B3, Distribusi!C:C, C3) | E3: 4500000 | F3: =D3*E3
A4: CSR | B4: Chainsaw | C4: Logistik Lainnya | D4: ='Stok Awal'!E4 + SUMIFS(Penerimaan!D:D, Penerimaan!A:A, A4, Penerimaan!B:B, B4, Penerimaan!C:C, C4) - SUMIFS(Distribusi!D:D, Distribusi!A:A, A4, Distribusi!B:B, B4, Distribusi!C:C, C4) | E4: 4500000 | F4: =D4*E4
A5: APBD | B5: Family Kit | C5: Logistik Lainnya | D5: ='Stok Awal'!E5 + SUMIFS(Penerimaan!D:D, Penerimaan!A:A, A5, Penerimaan!B:B, B5, Penerimaan!C:C, C5) - SUMIFS(Distribusi!D:D, Distribusi!A:A, A5, Distribusi!B:B, B5, Distribusi!C:C, C5) | E5: 350000 | F5: =D5*E5
A6: APBN | B6: Family Kit | C6: Logistik Lainnya | D6: ='Stok Awal'!E6 + SUMIFS(Penerimaan!D:D, Penerimaan!A:A, A6, Penerimaan!B:B, B6, Penerimaan!C:C, C6) - SUMIFS(Distribusi!D:D, Distribusi!A:A, A6, Distribusi!B:B, B6, Distribusi!C:C, C6) | E6: 350000 | F6: =D6*E6
A7: CSR | B7: Family Kit | C7: Logistik Lainnya | D7: ='Stok Awal'!E7 + SUMIFS(Penerimaan!D:D, Penerimaan!A:A, A7, Penerimaan!B:B, B7, Penerimaan!C:C, C7) - SUMIFS(Distribusi!D:D, Distribusi!A:A, A7, Distribusi!B:B, B7, Distribusi!C:C, C7) | E7: 350000 | F7: =D7*E7
A8: APBD | B8: Genset | C8: Logistik Lainnya | D8: ='Stok Awal'!E8 + SUMIFS(Penerimaan!D:D, Penerimaan!A:A, A8, Penerimaan!B:B, B8, Penerimaan!C:C, C8) - SUMIFS(Distribusi!D:D, Distribusi!A:A, A8, Distribusi!B:B, B8, Distribusi!C:C, C8) | E8: 12500000 | F8: =D8*E8
A9: APBN | B9: Genset | C9: Logistik Lainnya | D9: ='Stok Awal'!E9 + SUMIFS(Penerimaan!D:D, Penerimaan!A:A, A9, Penerimaan!B:B, B9, Penerimaan!C:C, C9) - SUMIFS(Distribusi!D:D, Distribusi!A:A, A9, Distribusi!B:B, B9, Distribusi!C:C, C9) | E9: 12500000 | F9: =D9*E9
A10: CSR | B10: Genset | C10: Logistik Lainnya | D10: ='Stok Awal'!E10 + SUMIFS(Penerimaan!D:D, Penerimaan!A:A, A10, Penerimaan!B:B, B10, Penerimaan!C:C, C10) - SUMIFS(Distribusi!D:D, Distribusi!A:A, A10, Distribusi!B:B, B10, Distribusi!C:C, C10) | E10: 12500000 | F10: =D10*E10
A11: APBD | B11: Perahu Karet | C11: Logistik Lainnya | D11: ='Stok Awal'!E11 + SUMIFS(Penerimaan!D:D, Penerimaan!A:A, A11, Penerimaan!B:B, B11, Penerimaan!C:C, C11) - SUMIFS(Distribusi!D:D, Distribusi!A:A, A11, Distribusi!B:B, B11, Distribusi!C:C, C11) | E11: 35000000 | F11: =D11*E11
A12: APBN | B12: Perahu Karet | C12: Logistik Lainnya | D12: ='Stok Awal'!E12 + SUMIFS(Penerimaan!D:D, Penerimaan!A:A, A12, Penerimaan!B:B, B12, Penerimaan!C:C, C12) - SUMIFS(Distribusi!D:D, Distribusi!A:A, A12, Distribusi!B:B, B12, Distribusi!C:C, C12) | E12: 35000000 | F12: =D12*E12
A13: CSR | B13: Perahu Karet | C13: Logistik Lainnya | D13: ='Stok Awal'!E13 + SUMIFS(Penerimaan!D:D, Penerimaan!A:A, A13, Penerimaan!B:B, B13, Penerimaan!C:C, C13) - SUMIFS(Distribusi!D:D, Distribusi!A:A, A13, Distribusi!B:B, B13, Distribusi!C:C, C13) | E13: 35000000 | F13: =D13*E13
... A61: CSR | B61: Selimut | C61: Sandang | D61: ='Stok Awal'!E61 + SUMIFS(Penerimaan!D:D, Penerimaan!A:A, A61, Penerimaan!B:B, B61, Penerimaan!C:C, C61) - SUMIFS(Distribusi!D:D, Distribusi!A:A, A61, Distribusi!B:B, B61, Distribusi!C:C, C61) | E61: 85000 | F61: =D61*E61
A62: TOTAL KESELURUHAN STOK | D62: =SUM(D2:D61) | F62: =SUM(F2:F61)

Sheet Kadaluwarsa
A1: Sumber Pendanaan | B1: Barang | C1: Kategori Barang | D1: Nomor Dokumen | E1: Tanggal Kadaluwarsa | F1: Status Kadaluwarsa | G1: Sisa Hari | H1: Harga Satuan (Rp)
A2: APBN | B2: Biskuit | C2: Pangan | D2: BAST-2025-IN-0039 | E2: 46162 | F2: -158 | H2: 25000
A3: APBN | B3: Susu Formula | C3: Pangan | D3: BAST-2025-IN-0078 | E3: 46176 | F3: -144 | H3: 65000
A4: APBD | B4: Susu Formula | C4: Pangan | D4: BAST-2025-IN-0029 | E4: 46177 | F4: -143 | H4: 65000
A5: APBN | B5: Susu Formula | C5: Pangan | D5: BAST-2025-IN-0033 | E5: 46188 | F5: -132 | H5: 65000
A6: APBD | B6: Susu Formula | C6: Pangan | D6: BAST-2025-IN-0100 | E6: 46225 | F6: -95 | H6: 65000
A7: CSR | B7: Susu Formula | C7: Pangan | D7: BAST-2026-IN-0070 | E7: 46237 | F7: -83 | H7: 65000
A8: APBN | B8: Makanan Siap Saji | C8: Pangan | D8: BAST-2025-IN-0021 | E8: 46267 | F8: -53 | H8: 45000
A9: APBD | B9: Susu Formula | C9: Pangan | D9: BAST-2026-IN-0028 | E9: 46270 | F9: -50 | H9: 65000
A10: APBN | B10: Makanan Siap Saji | C10: Pangan | D10: BAST-2025-IN-0057 | E10: 46274 | F10: -46 | H10: 45000
A11: APBN | B11: Susu Formula | C11: Pangan | D11: BAST-2025-IN-0114 | E11: 46306 | F11: -14 | H11: 65000
A12: APBD | B12: Air Mineral | C12: Pangan | D12: BAST-2025-IN-0092 | E12: 46312 | F12: -8 | H12: 30000
A13: APBN | B13: Susu Formula | C13: Pangan | D13: BAST-2026-IN-0045 | E13: 46313 | F13: -7 | H13: 65000
... A52: APBN | B52: Air Mineral | C52: Pangan | D52: BAST-2026-IN-0064 | E52: 47077 | F52: 757 | H52: 30000

Sheet Permohonan Daerah
A1: Nomor Surat Permohonan | B1: Tahun Anggaran | C1: Tanggal Permohonan | D1: Kab/Kota Pemohon | E1: Kategori Barang | F1: Barang | G1: Jumlah Diminta (Unit) | H1: Estimasi Harga Satuan (Rp) | I1: Estimasi Nilai Total (Rp)
A2: 360/001/BPBD-KAB/I/2025 | B2: 2025 | C2: 45677 | D2: Kabupaten Bandung | E2: Pangan | F2: Beras | G2: 760 | H2: 15000 | I2: 11400000
A3: 360/002/BPBD-KAB/I/2025 | B3: 2025 | C3: 45677 | D3: Kabupaten Bandung | E3: Sandang | F3: Selimut | G3: 760 | H3: 85000 | I3: 64600000
A4: 360/005/BPBD-KAB/I/2025 | B4: 2025 | C4: 45674 | D4: Kabupaten Bandung Barat | E4: Pangan | F4: Lauk Pauk | G4: 480 | H4: 35000 | I4: 16800000
A5: 360/006/BPBD-KAB/I/2025 | B5: 2025 | C5: 45680 | D5: Kabupaten Bekasi | E5: Pangan | F5: Beras | G5: 3940 | H5: 15000 | I5: 59100000
A6: 360/007/BPBD-KAB/I/2025 | B6: 2025 | C6: 45679 | D6: Kabupaten Bekasi | E6: Logistik Lainnya | F6: Chainsaw | G6: 10 | H6: 4500000 | I6: 45000000
A7: 360/009/BPBD-KAB/I/2025 | B7: 2025 | C7: 45679 | D7: Kabupaten Bogor | E7: Sandang | F7: Pakaian Anak | G7: 820 | H7: 75000 | I7: 61500000
A8: 360/012/BPBD-KAB/I/2025 | B8: 2025 | C8: 45681 | D8: Kabupaten Ciamis | E8: Pangan | F8: Beras | G8: 240 | H8: 15000 | I8: 3600000
A9: 360/013/BPBD-KAB/I/2025 | B9: 2025 | C9: 45673 | D9: Kabupaten Ciamis | E9: Sandang | F9: Selimut | G9: 240 | H9: 85000 | I9: 20400000
A10: 360/016/BPBD-KAB/I/2025 | B10: 2025 | C10: 45681 | D10: Kabupaten Cianjur | E10: Pangan | F10: Beras | G10: 750 | H10: 15000 | I10: 11250000
A11: 360/017/BPBD-KAB/I/2025 | B11: 2025 | C11: 45674 | D11: Kabupaten Cianjur | E11: Sandang | F11: Selimut | G11: 750 | H11: 85000 | I11: 63750000
A12: 360/020/BPBD-KAB/I/2025 | B12: 2025 | C12: 45674 | D12: Kabupaten Cirebon | E12: Pangan | F12: Susu Formula | G12: 1110 | H12: 65000 | I12: 72150000
A13: 360/022/BPBD-KAB/I/2025 | B13: 2025 | C13: 45673 | D13: Kabupaten Garut | E13: Papan | F13: Terpal | G13: 210 | H13: 150000 | I13: 31500000
... A89: 360/088/BPBD-KOTA/I/2026 | B89: 2026 | C89: 46044 | D89: Kota Tasikmalaya | E89: Logistik Lainnya | F89: Family Kit | G89: 330 | H89: 350000 | I89: 115500000
A90: TOTAL PERMOHONAN PENGUATAN | G90: =SUM(G2:G89) | I90: =SUM(I2:I89)

Sheet _RefData
A1: Sumber Pendanaan | B1: Kategori Barang | C1: Kab/Kota Jawa Barat | D1: Tahun Anggaran
A2: APBN | B2: Sandang | C2: - | D2: 2025
A3: APBD | B3: Pangan | C3: Kabupaten Bandung | D3: 2026
A4: CSR | B4: Papan | C4: Kabupaten Bandung Barat
B5: Logistik Lainnya | C5: Kabupaten Bekasi
C6: Kabupaten Bogor
C7: Kabupaten Ciamis
C8: Kabupaten Cianjur
C9: Kabupaten Cirebon
C10: Kabupaten Garut
C11: Kabupaten Indramayu
C12: Kabupaten Karawang
C13: Kabupaten Kuningan
C14: Kabupaten Majalengka
C15: Kabupaten Pangandaran
C16: Kabupaten Purwakarta
C17: Kabupaten Subang
... C29: Kota Tasikmalaya
